{
 "cells": [
  {
   "cell_type": "code",
   "execution_count": 3,
   "id": "657bcf66-cbba-447d-8118-0061c7268128",
   "metadata": {},
   "outputs": [
    {
     "ename": "ModuleNotFoundError",
     "evalue": "No module named 'pyper'",
     "output_type": "error",
     "traceback": [
      "\u001b[0;31m---------------------------------------------------------------------------\u001b[0m",
      "\u001b[0;31mModuleNotFoundError\u001b[0m                       Traceback (most recent call last)",
      "Cell \u001b[0;32mIn[3], line 1\u001b[0m\n\u001b[0;32m----> 1\u001b[0m \u001b[38;5;28;01mimport\u001b[39;00m \u001b[38;5;21;01mpyper\u001b[39;00m \u001b[38;5;28;01mas\u001b[39;00m \u001b[38;5;21;01mpr\u001b[39;00m\n",
      "\u001b[0;31mModuleNotFoundError\u001b[0m: No module named 'pyper'"
     ]
    }
   ],
   "source": [
    "import pyper as pr"
   ]
  },
  {
   "cell_type": "code",
   "execution_count": 2,
   "id": "1ab80efc-18e6-40f1-98b2-a78edcf16ac6",
   "metadata": {},
   "outputs": [
    {
     "name": "stdout",
     "output_type": "stream",
     "text": [
      "Defaulting to user installation because normal site-packages is not writeable\n",
      "Requirement already satisfied: PypeR in /home/m.giraud/.local/lib/python3.10/site-packages (1.1.2)\n"
     ]
    }
   ],
   "source": [
    "!pip install PypeR"
   ]
  },
  {
   "cell_type": "code",
   "execution_count": 4,
   "id": "9948e686-a5c7-44ca-87c2-401a018bb754",
   "metadata": {},
   "outputs": [],
   "source": [
    "import pyRserve"
   ]
  },
  {
   "cell_type": "code",
   "execution_count": 5,
   "id": "59cb3814-3421-4572-9a2d-09eeaa082d63",
   "metadata": {},
   "outputs": [
    {
     "ename": "RConnectionRefused",
     "evalue": "Connection denied, server not reachable or not accepting connections",
     "output_type": "error",
     "traceback": [
      "\u001b[0;31m---------------------------------------------------------------------------\u001b[0m",
      "\u001b[0;31mConnectionRefusedError\u001b[0m                    Traceback (most recent call last)",
      "File \u001b[0;32m~/.conda/envs/py38b/lib/python3.8/site-packages/pyRserve/rconn.py:117\u001b[0m, in \u001b[0;36mRConnector.connect\u001b[0;34m(self)\u001b[0m\n\u001b[1;32m    116\u001b[0m \u001b[38;5;28;01mtry\u001b[39;00m:\n\u001b[0;32m--> 117\u001b[0m     \u001b[38;5;28;43mself\u001b[39;49m\u001b[38;5;241;43m.\u001b[39;49m\u001b[43msock\u001b[49m\u001b[38;5;241;43m.\u001b[39;49m\u001b[43mconnect\u001b[49m\u001b[43m(\u001b[49m\u001b[43m(\u001b[49m\u001b[38;5;28;43mself\u001b[39;49m\u001b[38;5;241;43m.\u001b[39;49m\u001b[43mhost\u001b[49m\u001b[43m,\u001b[49m\u001b[43m \u001b[49m\u001b[38;5;28;43mself\u001b[39;49m\u001b[38;5;241;43m.\u001b[39;49m\u001b[43mport\u001b[49m\u001b[43m)\u001b[49m\u001b[43m)\u001b[49m\n\u001b[1;32m    118\u001b[0m \u001b[38;5;28;01mexcept\u001b[39;00m socket\u001b[38;5;241m.\u001b[39merror:\n",
      "\u001b[0;31mConnectionRefusedError\u001b[0m: [Errno 111] Connection refused",
      "\nDuring handling of the above exception, another exception occurred:\n",
      "\u001b[0;31mRConnectionRefused\u001b[0m                        Traceback (most recent call last)",
      "Cell \u001b[0;32mIn[5], line 1\u001b[0m\n\u001b[0;32m----> 1\u001b[0m conn \u001b[38;5;241m=\u001b[39m \u001b[43mpyRserve\u001b[49m\u001b[38;5;241;43m.\u001b[39;49m\u001b[43mconnect\u001b[49m\u001b[43m(\u001b[49m\u001b[43m)\u001b[49m\n",
      "File \u001b[0;32m~/.conda/envs/py38b/lib/python3.8/site-packages/pyRserve/rconn.py:70\u001b[0m, in \u001b[0;36mconnect\u001b[0;34m(host, port, atomicArray, defaultVoid, oobCallback)\u001b[0m\n\u001b[1;32m     68\u001b[0m     host \u001b[38;5;241m=\u001b[39m \u001b[38;5;124m'\u001b[39m\u001b[38;5;124mlocalhost\u001b[39m\u001b[38;5;124m'\u001b[39m\n\u001b[1;32m     69\u001b[0m \u001b[38;5;28;01massert\u001b[39;00m port \u001b[38;5;129;01mis\u001b[39;00m \u001b[38;5;129;01mnot\u001b[39;00m \u001b[38;5;28;01mNone\u001b[39;00m, \u001b[38;5;124m'\u001b[39m\u001b[38;5;124mport number must be given\u001b[39m\u001b[38;5;124m'\u001b[39m\n\u001b[0;32m---> 70\u001b[0m \u001b[38;5;28;01mreturn\u001b[39;00m \u001b[43mRConnector\u001b[49m\u001b[43m(\u001b[49m\u001b[43mhost\u001b[49m\u001b[43m,\u001b[49m\u001b[43m \u001b[49m\u001b[43mport\u001b[49m\u001b[43m,\u001b[49m\u001b[43m \u001b[49m\u001b[43matomicArray\u001b[49m\u001b[43m,\u001b[49m\u001b[43m \u001b[49m\u001b[43mdefaultVoid\u001b[49m\u001b[43m,\u001b[49m\u001b[43m \u001b[49m\u001b[43moobCallback\u001b[49m\u001b[43m)\u001b[49m\n",
      "File \u001b[0;32m~/.conda/envs/py38b/lib/python3.8/site-packages/pyRserve/rconn.py:103\u001b[0m, in \u001b[0;36mRConnector.__init__\u001b[0;34m(self, host, port, atomicArray, defaultVoid, oobCallback)\u001b[0m\n\u001b[1;32m    101\u001b[0m \u001b[38;5;28mself\u001b[39m\u001b[38;5;241m.\u001b[39mr \u001b[38;5;241m=\u001b[39m RNameSpace(\u001b[38;5;28mself\u001b[39m)\n\u001b[1;32m    102\u001b[0m \u001b[38;5;28mself\u001b[39m\u001b[38;5;241m.\u001b[39mref \u001b[38;5;241m=\u001b[39m RNameSpaceReference(\u001b[38;5;28mself\u001b[39m)\n\u001b[0;32m--> 103\u001b[0m \u001b[38;5;28;43mself\u001b[39;49m\u001b[38;5;241;43m.\u001b[39;49m\u001b[43mconnect\u001b[49m\u001b[43m(\u001b[49m\u001b[43m)\u001b[49m\n",
      "File \u001b[0;32m~/.conda/envs/py38b/lib/python3.8/site-packages/pyRserve/rconn.py:119\u001b[0m, in \u001b[0;36mRConnector.connect\u001b[0;34m(self)\u001b[0m\n\u001b[1;32m    117\u001b[0m     \u001b[38;5;28mself\u001b[39m\u001b[38;5;241m.\u001b[39msock\u001b[38;5;241m.\u001b[39mconnect((\u001b[38;5;28mself\u001b[39m\u001b[38;5;241m.\u001b[39mhost, \u001b[38;5;28mself\u001b[39m\u001b[38;5;241m.\u001b[39mport))\n\u001b[1;32m    118\u001b[0m \u001b[38;5;28;01mexcept\u001b[39;00m socket\u001b[38;5;241m.\u001b[39merror:\n\u001b[0;32m--> 119\u001b[0m     \u001b[38;5;28;01mraise\u001b[39;00m RConnectionRefused(\u001b[38;5;124m'\u001b[39m\u001b[38;5;124mConnection denied, server not reachable \u001b[39m\u001b[38;5;124m'\u001b[39m\n\u001b[1;32m    120\u001b[0m                              \u001b[38;5;124m'\u001b[39m\u001b[38;5;124mor not accepting connections\u001b[39m\u001b[38;5;124m'\u001b[39m)\n\u001b[1;32m    121\u001b[0m time\u001b[38;5;241m.\u001b[39msleep(\u001b[38;5;241m0.2\u001b[39m)\n\u001b[1;32m    122\u001b[0m hdr \u001b[38;5;241m=\u001b[39m \u001b[38;5;28mself\u001b[39m\u001b[38;5;241m.\u001b[39msock\u001b[38;5;241m.\u001b[39mrecv(\u001b[38;5;241m1024\u001b[39m)\n",
      "\u001b[0;31mRConnectionRefused\u001b[0m: Connection denied, server not reachable or not accepting connections"
     ]
    }
   ],
   "source": [
    "conn = pyRserve.connect()"
   ]
  },
  {
   "cell_type": "code",
   "execution_count": 6,
   "id": "42b4a5c2-25c0-4495-8dab-1306dce6b231",
   "metadata": {},
   "outputs": [
    {
     "name": "stdout",
     "output_type": "stream",
     "text": [
      "/bin/bash: R: command not found\n"
     ]
    }
   ],
   "source": [
    "!R"
   ]
  },
  {
   "cell_type": "code",
   "execution_count": null,
   "id": "7cb850c1-cdbd-4d7a-825f-f62fc7a3423f",
   "metadata": {},
   "outputs": [],
   "source": []
  }
 ],
 "metadata": {
  "kernelspec": {
   "display_name": "py38b",
   "language": "python",
   "name": "py38b"
  },
  "language_info": {
   "codemirror_mode": {
    "name": "ipython",
    "version": 3
   },
   "file_extension": ".py",
   "mimetype": "text/x-python",
   "name": "python",
   "nbconvert_exporter": "python",
   "pygments_lexer": "ipython3",
   "version": "3.8.15"
  }
 },
 "nbformat": 4,
 "nbformat_minor": 5
}
